# **promiseのキャッチ**

これまで`resolve`のケースを見てきましたが、次にエグゼキューター関数でエラーが発生した場合を見ていきましょう。
エラーが発生すると、 `.then（）`の2番目のコールバックが実行されます。

```js
const promise = new Promise((resolve, reject) => {
  if (Math.random() * 100 <= 90) {
    reject(new Error("I was rejected using the reject function"));
  }

  reject(new Error("10% of the times, I will fail"));
});

promise.then(
  () => console.log(resolved),
  error => console.log(error.message)
);

// 表示: I was rejected using the reject function
```

これは先ほどのものと同様の例ですが、今では、90％の時間でrejectし、他の10％のケースでエラーを投げます。

しかし、エラーを処理したいときに `.then（null、（）=> {...}）`を書く代わりに、 `onRejected`という1つのコールバックを受け入れる` .catch（） `を使用することができます。

```js
const promise = new Promise((resolve, reject) => {
  if (Math.random() * 100 <= 90) {
    reject(new Error("I was rejected using the reject function"));
  }

  reject(new Error("10% of the times, I will fail"));
});

promise.catch(error => console.log(error.message)); // 表示: I was rejected using the reject function
```

`.catch（）`は `.then（undefined、onRejected）`の単なる構文上のシュガー（糖衣構文）です。
